Workbook

Sheet Stocks
A1: Ticker | B1: Weight | C1: Sector | D1: Market Cap | E1: Country | F1: Communication | G1: Consumer Discretionary | H1: Consumer Staples | I1: Energy | J1: Financials | K1: Health Care | L1: Industrials | M1: Information Technology | N1: Materials | O1: Real Estate | P1: Utilities | Q1: size | R1: beta | S1: momentum | T1: residvol | U1: nlsize | V1: btop | W1: liquidity | X1: earnyild | Y1: growth | Z1: leverage | AA1: Idio Vol
A2: AES | B2: 0.05 | C2: Utilities | D2: 9.2845664e+09 | E2: 1 | F2: 0 | G2: 0 | H2: 0 | I2: 0 | J2: 0 | K2: 0 | L2: 0 | M2: 0 | N2: 0 | O2: 0 | P2: 1 | Q2: -1.8753286 | R2: 0.29395065 | S2: -0.4947023 | T2: 0.34999499 | U2: 3.1791986 | V2: 0.21530903 | W2: 0.76938576 | X2: 0.025940408 | Y2: 0.4018156 | Z2: 2.1466394 | AA2: =STDEVP(Residuals!B2:B245)*SQRT(252)
A3: AMZN | B3: 0.05 | C3: Consumer Discretionary | D3: 2.459585e+12 | E3: 1 | F3: 0 | G3: 1 | H3: 0 | I3: 0 | J3: 0 | K3: 0 | L3: 0 | M3: 0 | N3: 0 | O3: 0 | P3: 0 | Q3: 1.3557378 | R3: 0.51006495 | S3: -0.0028249758 | T3: 0.4972496 | U3: -2.4573468 | V3: -0.1202573 | W3: -1.0806622 | X3: -0.0070426723 | Y3: 0.70250401 | Z3: -0.24131279 | AA3: =STDEVP(Residuals!C2:C245)*SQRT(252)
A4: ASO | B4: 0.05 | C4: Consumer Discretionary | D4: 3.737031e+09 | E4: 1 | F4: 0 | G4: 1 | H4: 0 | I4: 0 | J4: 0 | K4: 0 | L4: 0 | M4: 0 | N4: 0 | O4: 0 | P4: 0 | Q4: -2.4023519 | R4: 1.4473628 | S4: -0.42771011 | T4: -0.74904462 | U4: 3.3589218 | V4: 0.49958099 | W4: 1.1074427 | X4: 0.25145157 | Y4: -0.8189211 | Z4: 0.096582546 | AA4: =STDEVP(Residuals!D2:D245)*SQRT(252)
A5: CCOI | B5: 0.05 | C5: Communication | D5: 1.8540629e+09 | E5: 1 | F5: 1 | G5: 0 | H5: 0 | I5: 0 | J5: 0 | K5: 0 | L5: 0 | M5: 0 | N5: 0 | O5: 0 | P5: 0 | Q5: -2.8082549 | R5: -0.32685386 | S5: -1.6149885 | T5: 0.83569421 | U5: 3.1543909 | V5: -0.28354209 | W5: 1.1474953 | X5: -0.15501889 | Y5: 0.31361695 | Z5: 4.5657038 | AA5: =STDEVP(Residuals!E2:E245)*SQRT(252)
A6: DLB | B6: 0.05 | C6: Information Technology | D6: 4.4068277e+09 | E6: 1 | F6: 0 | G6: 0 | H6: 0 | I6: 0 | J6: 0 | K6: 0 | L6: 0 | M6: 1 | N6: 0 | O6: 0 | P6: 0 | Q6: -2.3068782 | R6: -0.2091857 | S6: -0.62180866 | T6: -0.83154403 | U6: 3.3610378 | V6: 0.55242778 | W6: -0.54354396 | X6: 0.017669581 | Y6: -0.37577703 | Z6: -0.61793915 | AA6: =STDEVP(Residuals!F2:F245)*SQRT(252)
A7: FIZZ | B7: 0.05 | C7: Consumer Staples | D7: 3.9559563e+09 | E7: 1 | F7: 0 | G7: 0 | H7: 1 | I7: 0 | J7: 0 | K7: 0 | L7: 0 | M7: 0 | N7: 0 | O7: 0 | P7: 0 | Q7: -2.3693828 | R7: -1.6128703 | S7: -0.38983968 | T7: 0.18103681 | U7: 3.3615169 | V7: -0.13247021 | W7: -2.5392686 | X7: 0.025927582 | Y7: -0.45826997 | Z7: -0.44559355 | AA7: =STDEVP(Residuals!G2:G245)*SQRT(252)
A8: GE | B8: 0.05 | C8: Industrials | D8: 2.8601625e+11 | E8: 1 | F8: 0 | G8: 0 | H8: 0 | I8: 0 | J8: 0 | K8: 0 | L8: 1 | M8: 0 | N8: 0 | O8: 0 | P8: 0 | Q8: 0.10967371 | R8: -0.030720794 | S8: 0.91720349 | T8: 0.19906466 | U8: -0.15402021 | V8: -0.22189488 | W8: -0.85914486 | X8: -0.041462575 | Y8: 0.48587772 | Z8: -0.25152451 | AA8: =STDEVP(Residuals!H2:H245)*SQRT(252)
A9: JPM | B9: 0.05 | C9: Financials | D9: 7.9940874e+11 | E9: 1 | F9: 0 | G9: 0 | H9: 0 | I9: 0 | J9: 1 | K9: 0 | L9: 0 | M9: 0 | N9: 0 | O9: 0 | P9: 0 | Q9: 0.70489363 | R9: -0.090437439 | S9: 0.40488704 | T9: 0.15517779 | U9: -1.3617314 | V9: 0.33884349 | W9: -1.5008819 | X9: 0.078211699 | Y9: 0.066611025 | Z9: -0.15981053 | AA9: =STDEVP(Residuals!I2:I245)*SQRT(252)
A10: LIN | B10: 0.05 | C10: Materials | D10: 2.2385982e+11 | E10: 1 | F10: 0 | G10: 0 | H10: 0 | I10: 0 | J10: 0 | K10: 0 | L10: 0 | M10: 0 | N10: 1 | O10: 0 | P10: 0 | Q10: -0.032224069 | R10: -0.82665366 | S10: -0.38308946 | T10: 0.02452923 | U10: 0.14435137 | V10: -0.066565481 | W10: -1.3110954 | X10: -0.01462025 | Y10: -0.31742167 | Z10: 0.016220237 | AA10: =STDEVP(Residuals!J2:J245)*SQRT(252)
A11: LLY | B11: 0.05 | C11: Health Care | D11: 6.5613233e+11 | E11: 1 | F11: 0 | G11: 0 | H11: 0 | I11: 0 | J11: 0 | K11: 1 | L11: 0 | M11: 0 | N11: 0 | O11: 0 | P11: 0 | Q11: 0.59051427 | R11: -0.6595035 | S11: -0.75659482 | T11: 1.5363995 | U11: -1.1395305 | V11: -0.27958492 | W11: -0.66923148 | X11: -0.029280634 | Y11: 0.30933404 | Z11: 0.31347772 | AA11: =STDEVP(Residuals!K2:K245)*SQRT(252)
A12: META | B12: 0.05 | C12: Communication | D12: 1.6322192e+12 | E12: 1 | F12: 1 | G12: 0 | H12: 0 | I12: 0 | J12: 0 | K12: 0 | L12: 0 | M12: 0 | N12: 0 | O12: 0 | P12: 0 | Q12: 1.1182738 | R12: 0.75388554 | S12: 0.12880042 | T12: 0.48519389 | U12: -2.0974887 | V12: -0.14417638 | W12: -0.52485324 | X12: 0.0071379207 | Y12: 0.27052917 | Z12: -0.2976345 | AA12: =STDEVP(Residuals!L2:L245)*SQRT(252)
A13: MMS | B13: 0.05 | C13: Industrials | D13: 4.7584781e+09 | E13: 1 | F13: 0 | G13: 0 | H13: 0 | I13: 0 | J13: 0 | K13: 0 | L13: 1 | M13: 0 | N13: 0 | O13: 0 | P13: 0 | Q13: -2.2624185 | R13: -1.0523056 | S13: -0.8010676 | T13: -0.087506505 | U13: 3.3564797 | V13: 0.22970547 | W13: 0.086823593 | X13: 0.12409617 | Y13: -0.12242958 | Z13: 0.31825005 | AA13: =STDEVP(Residuals!M2:M245)*SQRT(252)
A14: NEE | B14: 0.05 | C14: Utilities | D14: 1.5167612e+11 | E14: 1 | F14: 0 | G14: 0 | H14: 0 | I14: 0 | J14: 0 | K14: 0 | L14: 0 | M14: 0 | N14: 0 | O14: 0 | P14: 1 | Q14: -0.25765456 | R14: -1.4193023 | S14: -0.40374957 | T14: 0.88151466 | U14: 0.61646181 | V14: 0.17401134 | W14: -0.91682962 | X14: 0.083174216 | Y14: 0.094599663 | Z14: 0.58187996 | AA14: =STDEVP(Residuals!N2:N245)*SQRT(252)
A15: NVDA | B15: 0.05 | C15: Information Technology | D15: 4.4132934e+12 | E15: 1 | F15: 0 | G15: 0 | H15: 0 | I15: 0 | J15: 0 | K15: 0 | L15: 0 | M15: 1 | N15: 0 | O15: 0 | P15: 0 | Q15: 1.6943003 | R15: 1.1595834 | S15: 0.9319097 | T15: 0.5799402 | U15: -2.8665141 | V15: -0.28720887 | W15: -0.062180233 | X15: -0.057612278 | Y15: 2.1511253 | Z15: -0.48940572 | AA15: =STDEVP(Residuals!O2:O245)*SQRT(252)
A16: PFS | B16: 0.05 | C16: Financials | D16: 2.5621972e+09 | E16: 1 | F16: 0 | G16: 0 | H16: 0 | I16: 0 | J16: 1 | K16: 0 | L16: 0 | M16: 0 | N16: 0 | O16: 0 | P16: 0 | Q16: -2.620922 | R16: 0.031852476 | S16: -0.12399986 | T16: -0.87530478 | U16: 3.2897704 | V16: 1.240329 | W16: -1.1474428 | X16: 0.17166068 | Y16: -0.30928687 | Z16: -0.029198796 | AA16: =STDEVP(Residuals!P2:P245)*SQRT(252)
A17: TVTX | B17: 0.05 | C17: Health Care | D17: 1.5603974e+09 | E17: 1 | F17: 0 | G17: 0 | H17: 0 | I17: 0 | J17: 0 | K17: 1 | L17: 0 | M17: 0 | N17: 0 | O17: 0 | P17: 0 | Q17: -2.9081155 | R17: 0.25293844 | S17: -0.18091205 | T17: 0.089364631 | U17: 3.0516647 | V17: -0.2897234 | W17: 0.73381114 | X17: -0.13557282 | Y17: 0.20809427 | Z17: 1.6859139 | AA17: =STDEVP(Residuals!Q2:Q245)*SQRT(252)
A18: USLM | B18: 0.05 | C18: Materials | D18: 3.5643435e+09 | E18: 1 | F18: 0 | G18: 0 | H18: 0 | I18: 0 | J18: 0 | K18: 0 | L18: 0 | M18: 0 | N18: 1 | O18: 0 | P18: 0 | Q18: -2.4297503 | R18: 0.30650987 | S18: 0.30711225 | T18: -0.32851936 | U18: 3.3552428 | V18: -0.087268582 | W18: -1.1114904 | X18: -0.022809315 | Y18: 0.40515162 | Z18: -0.62962494 | AA18: =STDEVP(Residuals!R2:R245)*SQRT(252)
A19: WHD | B19: 0.05 | C19: Energy | D19: 2.8544448e+09 | E19: 1 | F19: 0 | G19: 0 | H19: 0 | I19: 1 | J19: 0 | K19: 0 | L19: 0 | M19: 0 | N19: 0 | O19: 0 | P19: 0 | Q19: -2.5583714 | R19: 0.98240399 | S19: -0.72774199 | T19: -0.66201409 | U19: 3.3190168 | V19: 0.27349775 | W19: -0.038441062 | X19: 0.052288341 | Y19: 0.78901529 | Z19: -0.59430259 | AA19: =STDEVP(Residuals!S2:S245)*SQRT(252)
A20: WMT | B20: 0.05 | C20: Consumer Staples | D20: 7.6421583e+11 | E20: 1 | F20: 0 | G20: 0 | H20: 1 | I20: 0 | J20: 0 | K20: 0 | L20: 0 | M20: 0 | N20: 0 | O20: 0 | P20: 0 | Q20: 0.678821 | R20: -0.81717278 | S20: 0.1246094 | T20: 0.63330173 | U20: -1.311662 | V20: -0.14654059 | W20: -1.9947353 | X20: -0.00018746125 | Y20: -0.23678993 | Z20: -0.12598275 | AA20: =STDEVP(Residuals!T2:T245)*SQRT(252)
A21: XOM | B21: 0.05 | C21: Energy | D21: 4.6709676e+11 | E21: 1 | F21: 0 | G21: 0 | H21: 0 | I21: 1 | J21: 0 | K21: 0 | L21: 0 | M21: 0 | N21: 0 | O21: 0 | P21: 0 | Q21: 0.39371863 | R21: -0.95443029 | S21: -0.41468151 | T21: 0.5497982 | U21: -0.74400189 | V21: 0.50975538 | W21: -1.1992133 | X21: 0.10847592 | Y21: -0.42314638 | Z21: -0.44149451 | AA21: =STDEVP(Residuals!U2:U245)*SQRT(252)

Sheet Covariance
B1: Country | C1: Communication | D1: Consumer Discretionary | E1: Consumer Staples | F1: Energy | G1: Financials | H1: Health Care | I1: Industrials | J1: Information Technology | K1: Materials | L1: Real Estate | M1: Utilities | N1: size | O1: beta | P1: momentum | Q1: residvol | R1: nlsize | S1: btop | T1: liquidity | U1: earnyild | V1: growth | W1: leverage
A2: Country | B2: 9.5282739e-05 | C2: -4.0356071e-06 | D2: -2.8660591e-06 | E2: -3.1180053e-05 | F2: -2.5213632e-06 | G2: 5.8638175e-06 | H2: -1.8641268e-05 | I2: 5.3946326e-06 | J2: 1.5427062e-05 | K2: 6.0004837e-06 | L2: -1.4059413e-05 | M2: -2.5930921e-05 | N2: -3.4470018e-06 | O2: 2.3571944e-05 | P2: 1.4604169e-06 | Q2: 1.0785282e-05 | R2: -2.3619586e-06 | S2: 3.2337589e-07 | T2: 1.0438212e-05 | U2: -1.8240609e-06 | V2: -5.7069653e-07 | W2: -3.9687567e-07
A3: Communication | B3: -4.0356071e-06 | C3: 1.7392349e-05 | D3: 3.6153623e-06 | E3: 7.8896184e-07 | F3: -1.1850299e-05 | G3: -2.0242661e-06 | H3: -2.5748887e-06 | I3: -3.4469056e-06 | J3: -2.2015927e-06 | K3: -4.6791232e-06 | L3: -1.7652235e-06 | M3: -4.7189053e-06 | N3: -4.21037e-07 | O3: 1.9367105e-07 | P3: -1.6287951e-06 | Q3: -7.0017077e-07 | R3: -2.7610387e-07 | S3: -7.1071285e-07 | T3: -8.4052944e-07 | U3: -3.4229653e-07 | V3: 1.0800577e-06 | W3: 6.9864814e-08
A4: Consumer Discretionary | B4: -2.8660591e-06 | C4: 3.6153623e-06 | D4: 2.5454301e-05 | E4: 7.9364117e-06 | F4: -1.98723e-05 | G4: 1.6404247e-06 | H4: -2.018895e-06 | I4: 7.4397704e-07 | J4: -1.0254252e-05 | K4: 4.7149021e-06 | L4: 1.8904053e-06 | M4: -6.300466e-06 | N4: -2.199096e-06 | O4: 2.1466769e-08 | P4: -6.9369415e-06 | Q4: -3.7323532e-06 | R4: -7.8799598e-09 | S4: 9.8016305e-07 | T4: -2.6371457e-06 | U4: 1.0903215e-06 | V4: -2.2163685e-06 | W4: 1.0727999e-06
A5: Consumer Staples | B5: -3.1180053e-05 | C5: 7.8896184e-07 | D5: 7.9364117e-06 | E5: 5.2337926e-05 | F5: -7.5330954e-06 | G5: -7.2005119e-06 | H5: 6.3842604e-06 | I5: 4.1237293e-06 | J5: -1.8050074e-05 | K5: 9.3218552e-06 | L5: 1.8132467e-05 | M5: 2.7527863e-05 | N5: 2.0350442e-06 | O5: 3.3329724e-06 | P5: -2.834729e-06 | Q5: -8.089682e-06 | R5: 8.1034123e-07 | S5: -2.1390568e-07 | T5: -7.3593313e-06 | U5: 7.8163862e-07 | V5: -3.4193957e-06 | W5: 1.8506344e-06
A6: Energy | B6: -2.5213632e-06 | C6: -1.1850299e-05 | D6: -1.98723e-05 | E6: -7.5330954e-06 | F6: 0.00013406043 | G6: -1.1322093e-06 | H6: -1.7029411e-05 | I6: 1.3314504e-06 | J6: 3.0959248e-06 | K6: -1.0977394e-06 | L6: 3.5455349e-06 | M6: 7.5779105e-06 | N6: 4.1725802e-06 | O6: -5.8919557e-06 | P6: 5.8884321e-06 | Q6: -3.9493312e-07 | R6: 1.0211772e-06 | S6: 4.372898e-06 | T6: 3.062912e-06 | U6: 5.1014666e-07 | V6: -2.1932225e-06 | W6: 1.6746281e-06
A7: Financials | B7: 5.8638175e-06 | C7: -2.0242661e-06 | D7: 1.6404247e-06 | E7: -7.2005119e-06 | F7: -1.1322093e-06 | G7: 2.0621051e-05 | H7: -6.8528212e-06 | I7: 6.4525327e-07 | J7: -4.7117936e-06 | K7: 3.9990673e-07 | L7: -3.48903e-07 | M7: -3.9051794e-06 | N7: -6.3122134e-07 | O7: -9.3070349e-07 | P7: 7.9646663e-07 | Q7: -1.0779809e-07 | R7: 6.8967586e-07 | S7: -7.0045033e-07 | T7: 1.6032204e-06 | U7: -6.5664927e-08 | V7: -1.0444831e-07 | W7: 3.3375819e-07
A8: Health Care | B8: -1.8641268e-05 | C8: -2.5748887e-06 | D8: -2.018895e-06 | E8: 6.3842604e-06 | F8: -1.7029411e-05 | G8: -6.8528212e-06 | H8: 5.2385614e-05 | I8: -2.2785676e-06 | J8: -1.3438491e-05 | K8: 6.7663681e-08 | L8: 8.2453493e-06 | M8: 7.0228289e-06 | N8: 2.660346e-07 | O8: -2.9452107e-06 | P8: -5.6835642e-06 | Q8: -4.9814039e-06 | R8: 1.2692696e-07 | S8: 1.0174532e-06 | T8: -3.4708749e-06 | U8: -5.1787764e-07 | V8: -1.0466771e-06 | W8: -1.6298064e-07
A9: Industrials | B9: 5.3946326e-06 | C9: -3.4469056e-06 | D9: 7.4397704e-07 | E9: 4.1237293e-06 | F9: 1.3314504e-06 | G9: 6.4525327e-07 | H9: -2.2785676e-06 | I9: 1.5892757e-05 | J9: -4.9451155e-06 | K9: 7.8370561e-06 | L9: 2.8428526e-06 | M9: 4.0401939e-06 | N9: 6.1942982e-07 | O9: 4.2794708e-06 | P9: 2.0063141e-07 | Q9: 1.7222936e-06 | R9: 6.1991677e-07 | S9: -4.4266604e-07 | T9: 5.3125356e-07 | U9: 4.1207908e-07 | V9: -8.093146e-07 | W9: -6.544283e-07
A10: Information Technology | B10: 1.5427062e-05 | C10: -2.2015927e-06 | D10: -1.0254252e-05 | E10: -1.8050074e-05 | F10: 3.0959248e-06 | G10: -4.7117936e-06 | H10: -1.3438491e-05 | I10: -4.9451155e-06 | J10: 1.8562289e-05 | K10: -7.96143e-06 | L10: -1.2211783e-05 | M10: -1.1120646e-05 | N10: -1.2085143e-07 | O10: -2.3225686e-07 | P10: 4.1753883e-06 | Q10: 5.2215602e-06 | R10: -7.6011824e-07 | S10: -4.9419212e-07 | T10: 3.5040062e-06 | U10: -4.2348595e-07 | V10: 2.4787364e-06 | W10: -1.0500312e-06
A11: Materials | B11: 6.0004837e-06 | C11: -4.6791232e-06 | D11: 4.7149021e-06 | E11: 9.3218552e-06 | F11: -1.0977394e-06 | G11: 3.9990673e-07 | H11: 6.7663681e-08 | I11: 7.8370561e-06 | J11: -7.96143e-06 | K11: 4.0364509e-05 | L11: 3.7702071e-06 | M11: 6.3044995e-06 | N11: -2.1948841e-06 | O11: 1.446042e-06 | P11: -1.0239636e-06 | Q11: 3.1046323e-06 | R11: -5.6598889e-07 | S11: 8.7252065e-07 | T11: 7.1526006e-07 | U11: -8.180444e-08 | V11: -2.222793e-06 | W11: 4.1087849e-07
A12: Real Estate | B12: -1.4059413e-05 | C12: -1.7652235e-06 | D12: 1.8904053e-06 | E12: 1.8132467e-05 | F12: 3.5455349e-06 | G12: -3.48903e-07 | H12: 8.2453493e-06 | I12: 2.8428526e-06 | J12: -1.2211783e-05 | K12: 3.7702071e-06 | L12: 2.9829905e-05 | M12: 1.9932876e-05 | N12: 1.4464849e-06 | O12: 8.1224686e-07 | P12: 7.0152122e-07 | Q12: -3.4087524e-06 | R12: 9.9358703e-07 | S12: -1.440946e-08 | T12: -2.4706346e-06 | U12: -1.3623254e-07 | V12: -2.3370325e-06 | W12: 1.8565141e-06
A13: Utilities | B13: -2.5930921e-05 | C13: -4.7189053e-06 | D13: -6.300466e-06 | E13: 2.7527863e-05 | F13: 7.5779105e-06 | G13: -3.9051794e-06 | H13: 7.0228289e-06 | I13: 4.0401939e-06 | J13: -1.1120646e-05 | K13: 6.3044995e-06 | L13: 1.9932876e-05 | M13: 5.4471354e-05 | N13: 3.4025919e-06 | O13: -2.5056597e-07 | P13: 5.4778627e-06 | Q13: -2.2083514e-06 | R13: -1.8494817e-07 | S13: -1.3148456e-06 | T13: -2.2002126e-06 | U13: 3.7594297e-07 | V13: -8.2585356e-07 | W13: -1.1872443e-07
... A23: leverage | B23: -3.9687567e-07 | C23: 6.9864814e-08 | D23: 1.0727999e-06 | E23: 1.8506344e-06 | F23: 1.6746281e-06 | G23: 3.3375819e-07 | H23: -1.6298064e-07 | I23: -6.544283e-07 | J23: -1.0500312e-06 | K23: 4.1087849e-07 | L23: 1.8565141e-06 | M23: -1.1872443e-07 | N23: 1.1106357e-06 | O23: -4.5650561e-07 | P23: -1.3441904e-06 | Q23: -2.0106055e-06 | R23: 6.027256e-07 | S23: 7.8882232e-07 | T23: -9.8194504e-07 | U23: 4.3931681e-07 | V23: -1.0890475e-07 | W23: 2.4543594e-06

Sheet FactorReturns
A1: Date | B1: Country | C1: Communication | D1: Consumer Discretionary | E1: Consumer Staples | F1: Energy | G1: Financials | H1: Health Care | I1: Industrials | J1: Information Technology | K1: Materials | L1: Real Estate | M1: Utilities | N1: size | O1: beta | P1: momentum | Q1: residvol | R1: nlsize | S1: btop | T1: liquidity | U1: earnyild | V1: growth | W1: leverage
A2: 2025-08-01 | B2: -0.0065821984 | C2: 0.010121703 | D2: 0.0014674198 | E2: -0.0035747967 | F2: 0.0041456298 | G2: 0.0036290844 | H2: -0.012432308 | I2: 0.0077608353 | J2: -0.0045211301 | K2: 0.0022461189 | L2: -0.001320587 | M2: 0.012039513 | N2: -0.0022787818 | O2: -0.0025889678 | P2: 0.0075148497 | Q2: 0.0021648191 | R2: -0.0018723497 | S2: -0.00087001305 | T2: -0.0011014323 | U2: 0.00049921171 | V2: 0.00097103033 | W2: -0.00055882534
A3: 2025-08-04 | B3: -0.016937434 | C3: -0.0027030372 | D3: 0.0039924201 | E3: 0.0014795966 | F3: -0.0068379545 | G3: -0.003194818 | H3: 0.0089825451 | I3: -0.0037807642 | J3: -0.00074966533 | K3: 0.00076786243 | L3: 0.0037847371 | M3: 0.0015010853 | N3: 0.0026473611 | O3: -0.012629635 | P3: 0.0018398501 | Q3: 0.0017443871 | R3: 0.0021126555 | S3: -0.00046686074 | T3: 0.00013791347 | U3: -0.0026089769 | V3: -0.0012008818 | W3: -0.00066488743
A4: 2025-08-05 | B4: 0.015956439 | C4: 0.0056389715 | D4: -0.00092452123 | E4: -0.0030408641 | F4: -0.010814693 | G4: -0.00019325825 | H4: 0.00090696566 | I4: -0.0065865301 | J4: 0.0014809897 | K4: -3.7432297e-05 | L4: -7.6626967e-05 | M4: 0.007812862 | N4: -0.0037376175 | O4: 0.0055806776 | P4: 0.0034431045 | Q4: 0.0012862865 | R4: -0.0012059586 | S4: -0.0027392431 | T4: 0.000145222 | U4: -0.0015942277 | V4: 0.00019381049 | W4: -0.0005892714
A5: 2025-08-06 | B5: -0.0053978281 | C5: -0.0070441549 | D5: 0.0054219705 | E5: -0.0038447231 | F5: 0.010532192 | G5: 0.0020632634 | H5: -0.0013894471 | I5: 0.010485368 | J5: -0.0054304811 | K5: 0.01791477 | L5: 0.010300288 | M5: -0.0050107124 | N5: -0.0045190268 | O5: -0.00077513591 | P5: 0.0010426843 | Q5: 0.0032919765 | R5: -0.0024502202 | S5: 0.0028503854 | T5: 0.00073056409 | U5: 0.0022891697 | V5: -0.0026049343 | W5: -0.0011078566
A6: 2025-08-07 | B6: 0.0068600276 | C6: 0.0038577934 | D6: 0.0080391912 | E6: 0.0092648027 | F6: -0.011248127 | G6: -0.003568167 | H6: -0.01534278 | I6: -0.005579924 | J6: 0.0051445293 | K6: -0.0098958756 | L6: -0.0070383922 | M6: -0.009895929 | N6: 0.00021699472 | O6: 0.00033133252 | P6: 0.0016442931 | Q6: -0.00019363797 | R6: -0.0011865979 | S6: 0.00046480361 | T6: -0.0035162632 | U6: -0.00024100643 | V6: 0.0010656581 | W6: -0.0019775525
A7: 2025-08-08 | B7: -0.0020324022 | C7: -0.0077678262 | D7: -0.00024834844 | E7: 0.0065602216 | F7: -0.0053084892 | G7: -0.0025624452 | H7: 0.0022174602 | I7: 0.0036894615 | J7: -0.0011825468 | K7: 0.017993463 | L7: 0.0042566543 | M7: 0.0087101011 | N7: 0.00050407507 | O7: -0.0026526831 | P7: 0.00044286639 | Q7: -0.0012305258 | R7: -0.0024647923 | S7: 0.0026014968 | T7: 0.0054311675 | U7: 0.0035176027 | V7: -0.0016753041 | W7: 0.0021375536
A8: 2025-08-11 | B8: 0.0054476794 | C8: -0.0088620173 | D8: -0.0047375907 | E8: 0.0010393322 | F8: 0.003043568 | G8: 0.0026355607 | H8: 0.011707698 | I8: -0.0009989493 | J8: 0.00049042562 | K8: 0.0065542147 | L8: -0.0099853547 | M8: -0.0050189742 | N8: 9.306812e-05 | O8: -0.0010875224 | P8: 0.0031500668 | Q8: -0.0034613842 | R8: -0.0029435569 | S8: 0.0019511746 | T8: -0.0013480772 | U8: 0.00064895445 | V8: -0.0036140817 | W8: -0.000895716
A9: 2025-08-12 | B9: -0.0025889812 | C9: 0.0041436938 | D9: 0.0030740963 | E9: 0.0010916808 | F9: -0.0051947709 | G9: 0.0031578476 | H9: 0.0039349336 | I9: 0.00048195952 | J9: -0.0041483427 | K9: -0.00081568322 | L9: -0.0033967824 | M9: -0.001636417 | N9: -0.0016893568 | O9: -0.0013915199 | P9: 0.0036151358 | Q9: 5.4181405e-05 | R9: -0.0016498878 | S9: 0.00093403522 | T9: 0.00039293839 | U9: 0.0035409247 | V9: -8.6926661e-05 | W9: 0.0014499352
A10: 2025-08-13 | B10: 0.011997487 | C10: 0.0027421295 | D10: 0.0025202441 | E10: -0.00014743299 | F10: -0.01187504 | G10: -0.00018059769 | H10: 0.0010621729 | I10: 0.0015280525 | J10: -0.0010313213 | K10: 0.0012804482 | L10: -0.0047852221 | M10: -0.00023899096 | N10: -0.0058831896 | O10: 0.010171698 | P10: -0.003121656 | Q10: -0.0012329527 | R10: -0.00070054996 | S10: 0.0014592633 | T10: -0.0016944716 | U10: 0.0013292118 | V10: -0.001600514 | W10: -1.5661315e-05
A11: 2025-08-14 | B11: 0.0033180301 | C11: 0.0024618365 | D11: 0.0063462632 | E11: -0.0090253344 | F11: -0.011565936 | G11: -0.0018374723 | H11: 0.0048325557 | I11: -2.9909167e-05 | J11: -0.00052926436 | K11: 0.0048780701 | L11: -0.003756606 | M11: -0.0073927546 | N11: -0.0035882636 | O11: 0.0017394466 | P11: -0.010828894 | Q11: -0.00052223836 | R11: 0.0011735528 | S11: 0.00060722887 | T11: 0.0018821032 | U11: 0.0010913708 | V11: -0.0020796651 | W11: 0.00093437141
A12: 2025-08-15 | B12: -0.0018866597 | C12: 0.0014367012 | D12: -0.0020665221 | E12: -0.0057861631 | F12: 0.0072910813 | G12: 0.0078730361 | H12: 0.0072577723 | I12: -0.0051068301 | J12: -0.0029193663 | K12: -0.0020769516 | L12: 0.00121159 | M12: -0.0014732952 | N12: 0.0034046703 | O12: -0.0018229829 | P12: 0.00029330231 | Q12: 0.00063734086 | R12: -0.0014730964 | S12: 0.0014748587 | T12: 0.0011423078 | U12: 6.8313088e-05 | V12: 4.9356168e-05 | W12: 0.00086448916
A13: 2025-08-18 | B13: -0.0021667871 | C13: 0.0049733634 | D13: 0.0011530171 | E13: -0.0044597101 | F13: -0.0024600441 | G13: -0.0052817203 | H13: 0.0082949259 | I13: -0.0019596371 | J13: -0.0002598004 | K13: -0.0020452537 | L13: 0.0045075595 | M13: -0.0067792633 | N13: 0.0014969536 | O13: -0.0040973685 | P13: -0.0032690146 | Q13: 0.0035411824 | R13: 0.00035609282 | S13: -0.00012452503 | T13: 0.0028598108 | U13: 1.3693138e-05 | V13: 0.002429076 | W13: 0.00089186813
... A22: 2025-08-29 | B22: 0.0047012439 | C22: 0.00071542819 | D22: -0.0052104546 | E22: -0.0057853616 | F22: 0.0077655651 | G22: -0.003129116 | H22: -0.0043243719 | I22: -0.0044983735 | J22: 0.0067537241 | K22: -0.0021299947 | L22: -0.0023217408 | M22: -0.0062634722 | N22: 0.00075748015 | O22: 0.0036564235 | P22: 0.0033293279 | Q22: 0.0017463429 | R22: 0.00074990151 | S22: -0.00044756448 | T22: -0.00030852817 | U22: -0.00029250557 | V22: 0.0018308007 | W22: 0.00049853002

Sheet Residuals
A1: Date | B1: AES | C1: AMZN | D1: ASO | E1: CCOI | F1: DLB | G1: FIZZ | H1: GE | I1: JPM | J1: LIN | K1: LLY | L1: META | M1: MMS | N1: NEE | O1: NVDA | P1: PFS | Q1: TVTX | R1: USLM | S1: WHD | T1: WMT | U1: XOM
A2: 2025-02-07 | B2: 0.031757519 | C2: -0.0010906846 | D2: 0.0014363614 | E2: 0.0043285936 | F2: 0.0077737774 | G2: -0.0029337331 | H2: 0.00024873743 | I2: 0.0091308315 | J2: 0.0074395467 | K2: 0.041245782 | L2: 0.0021527457 | M2: -0.07942424 | N2: -0.0015251749 | O2: 0.02056915 | P2: 0.020341654 | Q2: 0.042731239 | R2: -0.006654376 | S2: 0.0056329886 | T2: -0.0078530112 | U2: 0.0073391653
A3: 2025-02-10 | B3: -0.029257273 | C3: -0.023157423 | D3: -0.008677737 | E3: 0.0090880939 | F3: 0.0066643111 | G3: 0.0090699863 | H3: 0.00065397483 | I3: 0.0023928449 | J3: -9.9575281e-05 | K3: 0.020722756 | L3: 0.0063152496 | M3: 0.0024869778 | N3: -0.013219491 | O3: 0.013853069 | P3: -0.010764518 | Q3: 0.0057906922 | R3: -0.030752773 | S3: 0.00068924578 | T3: -0.0097505175 | U3: 0.011182031
A4: 2025-02-11 | B4: 0.0033348673 | C4: 0.010206552 | D4: 0.045779018 | E4: 0.019206999 | F4: 0.0018300942 | G4: 0.0024271073 | H4: -0.012502695 | I4: -0.015690309 | J4: 0.0010501301 | K4: -0.01232199 | L4: -0.0080059063 | M4: -0.009452829 | N4: 0.010212764 | O4: 0.0072971468 | P4: 0.0080267957 | Q4: -0.026020291 | R4: -0.031012459 | S4: -0.0093382837 | T4: 0.012134259 | U4: -0.0099015606
A5: 2025-02-12 | B5: -0.057685505 | C5: -0.0019506623 | D5: 0.012727815 | E5: -0.0063802195 | F5: -0.0017440229 | G5: -0.024419924 | H5: 0.022857668 | I5: 0.010041358 | J5: -0.0065808962 | K5: -0.0025648877 | L5: 0.004217081 | M5: -0.023582699 | N5: 0.00078330461 | O5: 0.014524907 | P5: 0.016033221 | Q5: 0.14499839 | R5: 0.0070618703 | S5: -0.0070681909 | T5: -0.015932735 | U5: -0.0077466412
A6: 2025-02-13 | B6: -0.013490909 | C6: -0.017054188 | D6: -0.0065925752 | E6: 0.0056272456 | F6: 0.0018484035 | G6: 0.0045599371 | H6: 0.013137272 | I6: 0.0091833056 | J6: 0.0040693971 | K6: 0.0076929408 | L6: 0.0039398586 | M6: 0.0042382486 | N6: -0.015043417 | O6: -0.020926837 | P6: -0.026478139 | Q6: -0.028976213 | R6: -0.0019193755 | S6: 0.0096439996 | T6: 0.013761796 | U6: -0.0026943618
A7: 2025-02-14 | B7: 0.0026923361 | C7: -0.010651571 | D7: 0.00044619808 | E7: 0.0057314401 | F7: 0.0033605227 | G7: -0.0066463912 | H7: -0.0085184751 | I7: -0.0078254265 | J7: -0.007567599 | K7: -0.008423517 | L7: -0.0022967875 | M7: 0.0021230967 | N7: -0.013868629 | O7: 0.012334934 | P7: -0.00042529483 | Q7: 0.0037908911 | R7: -0.019086563 | S7: 0.0097392774 | T7: -0.00039929815 | U7: 0.0018661535
A8: 2025-02-18 | B8: -0.017775606 | C8: -0.010073163 | D8: -0.0073707401 | E8: -0.0068577157 | F8: -0.0035423409 | G8: 0.011543467 | H8: 0.00022342052 | I8: -0.00064085528 | J8: -0.0014499663 | K8: -0.027366333 | L8: 0.0077710937 | M8: 0.010120821 | N8: -0.0026689919 | O8: 0.025408561 | P8: -0.0034363699 | Q8: -0.029844853 | R8: 0.028758262 | S8: 0.00076437509 | T8: 0.0016683805 | U8: -0.0012317789
A9: 2025-02-19 | B9: 0.015679301 | C9: -0.0018246936 | D9: -0.023610979 | E9: 0.022856313 | F9: -0.00063400873 | G9: -0.0099444494 | H9: 0.0074887082 | I9: 0.011074218 | J9: 0.0094290061 | K9: 0.020602763 | L9: -0.017400964 | M9: -0.0054946228 | N9: -0.0036382278 | O9: 0.0014005711 | P9: -0.0036325751 | Q9: -0.0032434723 | R9: 0.016484387 | S9: 0.010942612 | T9: 0.0075128335 | U9: 0.0097263184
A10: 2025-02-20 | B10: 0.0087091214 | C10: -0.002490088 | D10: -0.014376978 | E10: 0.0064845721 | F10: -0.0090940944 | G10: -0.0051896656 | H10: 0.0015450002 | I10: -0.0049786012 | J10: 0.0007654327 | K10: -0.0065509958 | L10: -0.018485312 | M10: 0.0083069269 | N10: 0.0010398104 | O10: 0.00030878961 | P10: -0.0047409324 | Q10: 0.028072673 | R10: -0.0091326276 | S10: -0.012160959 | T10: -0.013095702 | U10: -0.010302118
A11: 2025-02-21 | B11: 0.016742796 | C11: -0.0078982027 | D11: 0.0044072623 | E11: -0.015649045 | F11: -0.007126088 | G11: 0.0034004476 | H11: 0.0032165149 | I11: -0.03149346 | J11: -5.7868051e-05 | K11: 0.004615792 | L11: -0.0039296961 | M11: -0.015725844 | N11: 0.013055565 | O11: 0.022251426 | P11: 0.0055379533 | Q11: 0.030719473 | R11: -0.0045793095 | S11: -0.0082046501 | T11: -0.058932828 | U11: 0.0083518251
A12: 2025-02-24 | B12: -0.0072137894 | C12: -0.0057556704 | D12: 0.017274967 | E12: -0.0010232882 | F12: 0.017301715 | G12: 0.016186128 | H12: -0.01594378 | I12: 0.008333971 | J12: 0.006711976 | K12: 0.0045454107 | L12: 0.0023141145 | M12: 0.01576945 | N12: 0.015764444 | O12: 0.005723262 | P12: 0.013006083 | Q12: -0.029873964 | R12: -0.023861826 | S12: 0.012100597 | T12: -0.037272131 | U12: 0.0024061668
A13: 2025-02-25 | B13: 0.0095298968 | C13: -0.010960511 | D13: -0.0021251128 | E13: -0.019037496 | F13: 0.0088878934 | G13: -0.00077220405 | H13: 0.0062732379 | I13: -0.0050143783 | J13: 0.0013444943 | K13: 0.0078906718 | L13: -0.018469179 | M13: 0.0074869209 | N13: -0.0072511377 | O13: -0.0001154401 | P13: -0.018509138 | Q13: -0.018491111 | R13: -0.0013378085 | S13: 0.0083359773 | T13: -0.0085224084 | U13: 0.0072349894
... A245: 2026-01-29 | B245: 0.022101692 | C245: -0.00099964021 | D245: 0.02678339 | E245: -0.006918487 | F245: -0.0012136529 | G245: 0.010465819 | H245: -0.014898966 | I245: 0.0015969896 | J245: -0.0022192246 | K245: -0.0028788523 | L245: -0.0072137821 | M245: -0.014483562 | N245: 0.0066513509 | O245: 0.01052613 | P245: 0.07107704 | Q245: 0.020867207 | R245: -0.024134289 | S245: -0.032039626 | T245: 0.0049105847 | U245: -0.0035364621

Sheet RiskDecomp
A1: PORTFOLIO FACTOR EXPOSURES
A2: Factor | B2: Exposure (formula) | C2: Python Reference
A3: b_k = SUMPRODUCT(weights, stock_exposures_k)
A4: Country | B4: =SUMPRODUCT(Stocks!$B$2:$B$21,Stocks!E$2:E$21) | C4: 1
A5: Communication | B5: =SUMPRODUCT(Stocks!$B$2:$B$21,Stocks!F$2:F$21) | C5: 0.1
A6: Consumer Discretionary | B6: =SUMPRODUCT(Stocks!$B$2:$B$21,Stocks!G$2:G$21) | C6: 0.1
A7: Consumer Staples | B7: =SUMPRODUCT(Stocks!$B$2:$B$21,Stocks!H$2:H$21) | C7: 0.1
A8: Energy | B8: =SUMPRODUCT(Stocks!$B$2:$B$21,Stocks!I$2:I$21) | C8: 0.1
A9: Financials | B9: =SUMPRODUCT(Stocks!$B$2:$B$21,Stocks!J$2:J$21) | C9: 0.1
A10: Health Care | B10: =SUMPRODUCT(Stocks!$B$2:$B$21,Stocks!K$2:K$21) | C10: 0.1
A11: Industrials | B11: =SUMPRODUCT(Stocks!$B$2:$B$21,Stocks!L$2:L$21) | C11: 0.1
A12: Information Technology | B12: =SUMPRODUCT(Stocks!$B$2:$B$21,Stocks!M$2:M$21) | C12: 0.1
A13: Materials | B13: =SUMPRODUCT(Stocks!$B$2:$B$21,Stocks!N$2:N$21) | C13: 0.1
A14: Real Estate | B14: =SUMPRODUCT(Stocks!$B$2:$B$21,Stocks!O$2:O$21) | C14: 0
A15: Utilities | B15: =SUMPRODUCT(Stocks!$B$2:$B$21,Stocks!P$2:P$21) | C15: 0.1
A16: size | B16: =SUMPRODUCT(Stocks!$B$2:$B$21,Stocks!Q$2:Q$21) | C16: -0.90928597
A17: beta | B17: =SUMPRODUCT(Stocks!$B$2:$B$21,Stocks!R$2:R$21) | C17: -0.1130442
A18: momentum | B18: =SUMPRODUCT(Stocks!$B$2:$B$21,Stocks!S$2:S$21) | C18: -0.22645944
A19: residvol | B19: =SUMPRODUCT(Stocks!$B$2:$B$21,Stocks!T$2:T$21) | C19: 0.17321634
A20: nlsize | B20: =SUMPRODUCT(Stocks!$B$2:$B$21,Stocks!U$2:U$21) | C20: 1.0707879
A21: btop | B21: =SUMPRODUCT(Stocks!$B$2:$B$21,Stocks!V$2:V$21) | C21: 0.098711376
A22: liquidity | B22: =SUMPRODUCT(Stocks!$B$2:$B$21,Stocks!W$2:W$21) | C22: -0.58270279
A23: earnyild | B23: =SUMPRODUCT(Stocks!$B$2:$B$21,Stocks!X$2:X$21) | C23: 0.02412136
A24: growth | B24: =SUMPRODUCT(Stocks!$B$2:$B$21,Stocks!Y$2:Y$21) | C24: 0.15681161
A25: leverage | B25: =SUMPRODUCT(Stocks!$B$2:$B$21,Stocks!Z$2:Z$21) | C25: 0.27004217
A27: COVARIANCE × EXPOSURE VECTOR (Ω × b)
A28: Factor | B28: (Ω×b)_k (formula) | C28: Python Reference
A29: (Ω×b)_k = SUMPRODUCT(Covariance row k, exposure vector)
A30: Country | B30: =SUMPRODUCT(TRANSPOSE(Covariance!B$2:W$2),$B$4:$B$25) | C30: 8.3220637e-05
A31: Communication | B31: =SUMPRODUCT(TRANSPOSE(Covariance!B$3:W$3),$B$4:$B$25) | C31: -4.0930631e-06
A32: Consumer Discretionary | B32: =SUMPRODUCT(TRANSPOSE(Covariance!B$4:W$4),$B$4:$B$25) | C32: 2.2149358e-06
A33: Consumer Staples | B33: =SUMPRODUCT(TRANSPOSE(Covariance!B$5:W$5),$B$4:$B$25) | C33: -2.1485551e-05
A34: Energy | B34: =SUMPRODUCT(TRANSPOSE(Covariance!B$6:W$6),$B$4:$B$25) | C34: 1.5647406e-06
A35: Financials | B35: =SUMPRODUCT(TRANSPOSE(Covariance!B$7:W$7),$B$4:$B$25) | C35: 5.8992538e-06
A36: Health Care | B36: =SUMPRODUCT(TRANSPOSE(Covariance!B$8:W$8),$B$4:$B$25) | C36: -1.3921065e-05
A37: Industrials | B37: =SUMPRODUCT(TRANSPOSE(Covariance!B$9:W$9),$B$4:$B$25) | C37: 7.0117487e-06
A38: Information Technology | B38: =SUMPRODUCT(TRANSPOSE(Covariance!B$10:W$10),$B$4:$B$25) | C38: 7.6100163e-06
A39: Materials | B39: =SUMPRODUCT(TRANSPOSE(Covariance!B$11:W$11),$B$4:$B$25) | C39: 1.2953375e-05
A40: Real Estate | B40: =SUMPRODUCT(TRANSPOSE(Covariance!B$12:W$12),$B$4:$B$25) | C40: -9.1787191e-06
A41: Utilities | B41: =SUMPRODUCT(TRANSPOSE(Covariance!B$13:W$13),$B$4:$B$25) | C41: -2.1727872e-05
...

Sheet Regression
A1: SINGLE-DAY REGRESSION: 2025-08-15
A3: Factor | B3: Factor Return (from full-universe WLS)
A4: Country | B4: -0.0018866597
A5: Communication | B5: 0.0014367012
A6: Consumer Discretionary | B6: -0.0020665221
A7: Consumer Staples | B7: -0.0057861631
A8: Energy | B8: 0.0072910813
A9: Financials | B9: 0.0078730361
A10: Health Care | B10: 0.0072577723
A11: Industrials | B11: -0.0051068301
A12: Information Technology | B12: -0.0029193663
A13: Materials | B13: -0.0020769516
A14: Real Estate | B14: 0.00121159
A15: Utilities | B15: -0.0014732952
... A25: leverage | B25: 0.00086448916
A27: PER-STOCK BREAKDOWN
A28: Ticker | B28: Actual Return | C28: Exp: Country | D28: Exp: Communication | E28: Exp: Consumer Discretionary | F28: Exp: Consumer Staples | G28: Exp: Energy | H28: Exp: Financials | I28: Exp: Health Care | J28: Exp: Industrials | K28: Exp: Information Technology | L28: Exp: Materials | M28: Exp: Real Estate | N28: Exp: Utilities | O28: Exp: size | P28: Exp: beta | Q28: Exp: momentum | R28: Exp: residvol | S28: Exp: nlsize | T28: Exp: btop | U28: Exp: liquidity | V28: Exp: earnyild | W28: Exp: growth | X28: Exp: leverage | Y28: Predicted (formula) | Z28: Residual (formula) | AA28: Python Predicted | AB28: Python Residual
A29: AES | B29: -0.0084648765 | C29: 1 | D29: 0 | E29: 0 | F29: 0 | G29: 0 | H29: 0 | I29: 0 | J29: 0 | K29: 0 | L29: 0 | M29: 0 | N29: 1 | O29: -1.8876695 | P29: 0.26196291 | Q29: -0.5043025 | R29: 0.37446178 | S29: 3.203954 | T29: 0.2211473 | U29: 0.90730728 | V29: 0.028361302 | W29: 0.40205394 | X29: 2.1420431 | Y29: =SUMPRODUCT(C29:X29,TRANSPOSE($B$4:$B$25)) | Z29: =B29-Y29 | AA29: -0.011657248 | AB29: 0.0031923715
A30: AMZN | B30: 0.028188187 | C30: 1 | D30: 0 | E30: 1 | F30: 0 | G30: 0 | H30: 0 | I30: 0 | J30: 0 | K30: 0 | L30: 0 | M30: 0 | N30: 0 | O30: 1.3336632 | P30: 0.47126113 | Q30: -0.0064504614 | R30: 0.55840253 | S30: -2.4377848 | T30: -0.11425995 | U30: -1.1111199 | V30: -0.0051076889 | W30: 0.70274251 | X30: -0.2392123 | Y30: =SUMPRODUCT(C30:X30,TRANSPOSE($B$4:$B$25)) | Z30: =B30-Y30 | AA30: 0.0020632745 | AB30: 0.026124913
A31: ASO | B31: -0.0061840791 | C31: 1 | D31: 0 | E31: 1 | F31: 0 | G31: 0 | H31: 0 | I31: 0 | J31: 0 | K31: 0 | L31: 0 | M31: 0 | N31: 0 | O31: -2.4114568 | P31: 1.4274636 | Q31: -0.5326743 | R31: -0.75585463 | S31: 3.3775228 | T31: 0.50282876 | U31: 1.1441989 | V31: 0.25271499 | W31: -0.81868344 | X31: 0.098165495 | Y31: =SUMPRODUCT(C31:X31,TRANSPOSE($B$4:$B$25)) | Z31: =B31-Y31 | AA31: -0.018268679 | AB31: 0.0120846
A32: CCOI | B32: -0.020009533 | C32: 1 | D32: 1 | E32: 0 | F32: 0 | G32: 0 | H32: 0 | I32: 0 | J32: 0 | K32: 0 | L32: 0 | M32: 0 | N32: 0 | O32: -2.8665743 | P32: -0.26912961 | Q32: -1.2894213 | R32: 0.82566924 | S32: 3.1201569 | T32: -0.27315406 | U32: 0.91361868 | V32: -0.15602872 | W32: 0.31385524 | X32: 4.5869864 | Y32: =SUMPRODUCT(C32:X32,TRANSPOSE($B$4:$B$25)) | Z32: =B32-Y32 | AA32: -0.0095563273 | AB32: -0.010453206
A33: DLB | B33: -0.016273931 | C33: 1 | D33: 0 | E33: 0 | F33: 0 | G33: 0 | H33: 0 | I33: 0 | J33: 0 | K33: 1 | L33: 0 | M33: 0 | N33: 0 | O33: -2.2966284 | P33: -0.26684916 | Q33: -0.64020163 | R33: -0.80886143 | S33: 3.3790743 | T33: 0.52625585 | U33: -0.68292893 | V33: 0.015210738 | W33: -0.37553912 | X33: -0.61556601 | Y33: =SUMPRODUCT(C33:X33,TRANSPOSE($B$4:$B$25)) | Z33: =B33-Y33 | AA33: -0.01837343 | AB33: 0.0020994991
A34: FIZZ | B34: -0.033361921 | C34: 1 | D34: 0 | E34: 0 | F34: 1 | G34: 0 | H34: 0 | I34: 0 | J34: 0 | K34: 0 | L34: 0 | M34: 0 | N34: 0 | O34: -2.3094747 | P34: -1.7986246 | Q34: -0.4830524 | R34: 0.058235879 | S34: 3.3800762 | T34: -0.14735616 | U34: -2.5410864 | V34: 0.012025959 | W34: -0.45803211 | X34: -0.44377568 | Y34: =SUMPRODUCT(C34:X34,TRANSPOSE($B$4:$B$25)) | Z34: =B34-Y34 | AA34: -0.02086616 | AB34: -0.012495761
A35: GE | B35: 0.0031196453 | C35: 1 | D35: 0 | E35: 0 | F35: 0 | G35: 0 | H35: 0 | I35: 0 | J35: 1 | K35: 0 | L35: 0 | M35: 0 | N35: 0 | O35: 0.094146591 | P35: 0.031318295 | Q35: 0.91825564 | R35: 0.18805054 | S35: -0.12250104 | T35: -0.21565108 | U35: -0.72270625 | V35: -0.039666442 | W35: 0.4861161 | X35: -0.24958319 | Y35: =SUMPRODUCT(C35:X35,TRANSPOSE($B$4:$B$25)) | Z35: =B35-Y35 | AA35: -0.0074984966 | AB35: 0.010618142
A36: JPM | B36: 0.012416912 | C36: 1 | D36: 0 | E36: 0 | F36: 0 | G36: 0 | H36: 1 | I36: 0 | J36: 0 | K36: 0 | L36: 0 | M36: 0 | N36: 0 | O36: 0.67964998 | P36: -0.09651545 | Q36: 0.34795248 | R36: 0.18500445 | S36: -1.3193404 | T36: 0.34846425 | U36: -1.4871697 | V36: 0.08162469 | W36: 0.066849175 | X36: -0.15764103 | Y36: =SUMPRODUCT(C36:X36,TRANSPOSE($B$4:$B$25)) | Z36: =B36-Y36 | AA36: 0.0093275146 | AB36: 0.0030893977
A37: LIN | B37: 0.0041961382 | C37: 1 | D37: 0 | E37: 0 | F37: 0 | G37: 0 | H37: 0 | I37: 0 | J37: 0 | K37: 0 | L37: 1 | M37: 0 | N37: 0 | O37: -0.046207292 | P37: -0.81314137 | Q37: -0.40104269 | R37: 0.04465255 | S37: 0.1738766 | T37: -0.062224221 | U37: -1.3309026 | V37: -0.013192581 | W37: -0.31718373 | X37: 0.017797798 | Y37: =SUMPRODUCT(C37:X37,TRANSPOSE($B$4:$B$25)) | Z37: =B37-Y37 | AA37: -0.0045971365 | AB37: 0.0087932747
A38: LLY | B38: 0.035604353 | C38: 1 | D38: 0 | E38: 0 | F38: 0 | G38: 0 | H38: 0 | I38: 1 | J38: 0 | K38: 0 | L38: 0 | M38: 0 | N38: 0 | O38: 0.52051555 | P38: -0.65582756 | Q38: -0.64277162 | R38: 1.4629941 | S38: -1.0052788 | T38: -0.26890127 | U38: -0.81029739 | V38: -0.019470148 | W38: 0.30957232 | X38: 0.3164734 | Y38: =SUMPRODUCT(C38:X38,TRANSPOSE($B$4:$B$25)) | Z38: =B38-Y38 | AA38: 0.0095289677 | AB38: 0.026075385
A39: META | B39: 0.0026243951 | C39: 1 | D39: 1 | E39: 0 | F39: 0 | G39: 0 | H39: 0 | I39: 0 | J39: 0 | K39: 0 | L39: 0 | M39: 0 | N39: 0 | O39: 1.1333666 | P39: 0.76241566 | Q39: 0.25967153 | R39: 0.54580876 | S39: -2.1318153 | T39: -0.14874357 | U39: -0.5632803 | V39: 0.0015989425 | W39: 0.27076744 | X39: -0.29580067 | Y39: =SUMPRODUCT(C39:X39,TRANSPOSE($B$4:$B$25)) | Z39: =B39-Y39 | AA39: 0.0044782499 | AB39: -0.0018538548
A40: MMS | B40: -0.013402615 | C40: 1 | D40: 0 | E40: 0 | F40: 0 | G40: 0 | H40: 0 | I40: 0 | J40: 1 | K40: 0 | L40: 0 | M40: 0 | N40: 0 | O40: -2.2747269 | P40: -1.1074337 | Q40: -0.83127722 | R40: -0.043195097 | S40: 3.3766966 | T40: 0.23681009 | U40: -0.02198411 | V40: 0.1268511 | W40: -0.12219153 | X40: 0.31962849 | Y40: =SUMPRODUCT(C40:X40,TRANSPOSE($B$4:$B$25)) | Z40: =B40-Y40 | AA40: -0.017361798 | AB40: 0.0039591836
... A48: XOM | B48: -0.0020466839 | C48: 1 | D48: 0 | E48: 0 | F48: 0 | G48: 1 | H48: 0 | I48: 0 | J48: 0 | K48: 0 | L48: 0 | M48: 0 | N48: 0 | O48: 0.35440015 | P48: -0.96842984 | Q48: -0.34914174 | R48: 0.56847014 | S48: -0.66670092 | T48: 0.54226134 | U48: -1.2353352 | V48: 0.11809203 | W48: -0.4229085 | X48: -0.43859768 | Y48: =SUMPRODUCT(C48:X48,TRANSPOSE($B$4:$B$25)) | Z48: =B48-Y48 | AA48: 0.0086151451 | AB48: -0.010661829

Sheet Universe
A1: Ticker | B1: Sector | C1: Return | D1: Market Cap | E1: sqrt(mcap) | F1: mcap_weight | G1: wls_weight | H1: Communication | I1: Consumer Discretionary | J1: Consumer Staples | K1: Energy | L1: Financials | M1: Health Care | N1: Industrials | O1: Information Technology | P1: Materials | Q1: Real Estate | R1: Utilities | S1: size | T1: beta | U1: momentum | V1: btop | W1: dastd | X1: cmra | Y1: hsigma | Z1: stom | AA1: stoq | AB1: stoa | AC1: etop | AD1: cetop | AE1: egro | AF1: sgro | AG1: mlev | AH1: dtoa | AI1: blev
A2: A | B2: Health Care | C2: -0.011875044 | D2: 3.397302e+10 | E2: =SQRT(D2) | F2: =D2/SUM($D$2:$D$2546) | G2: =E2/SUM($E$2:$E$2546) | H2: 0 | I2: 0 | J2: 0 | K2: 0 | L2: 0 | M2: 1 | N2: 0 | O2: 0 | P2: 0 | Q2: 0 | R2: 0 | S2: 24.248833 | T2: 1.1406879 | U2: -0.00074811895 | V2: 0.18750173 | W2: 0.020443253 | X2: 0.34619534 | Y2: 0.015837532 | Z2: -2.1930009 | AA2: -1.958197 | AB2: -1.9918133 | AC2: 0.039560805 | AD2: 0.04803812 | AE2: 0.033511586 | AF2: -0.025110198 | AG2: 1.0986077 | AH2: 0.278832 | AI2: 1.5259027
A3: AA | B3: Materials | C3: -0.012686534 | D3: 8.1948404e+09 | E3: =SQRT(D3) | F3: =D3/SUM($D$2:$D$2546) | G3: =E3/SUM($E$2:$E$2546) | H3: 0 | I3: 0 | J3: 0 | K3: 0 | L3: 0 | M3: 0 | N3: 0 | O3: 0 | P3: 1 | Q3: 0 | R3: 0 | S3: 22.826771 | T3: 1.7224227 | U3: -0.00067131218 | V3: 0.7486418 | W3: 0.031950922 | X3: 0.66522429 | Y3: 0.022725453 | Z3: -0.67467393 | AA3: -0.70170703 | AB3: -0.80060533 | AC3: 0.08005037 | AD3: 0.15473151 | AE3: -0.52772134 | AF3: -0.02270824 | AG3: 1.3141001 | AH3: 0.17671781 | AI3: 1.4195599
A4: AAL | B4: Industrials | C4: -0.022368844 | D4: 8.6565469e+09 | E4: =SQRT(D4) | F4: =D4/SUM($D$2:$D$2546) | G4: =E4/SUM($E$2:$E$2546) | H4: 0 | I4: 0 | J4: 0 | K4: 0 | L4: 0 | M4: 0 | N4: 1 | O4: 0 | P4: 0 | Q4: 0 | R4: 0 | S4: 22.881582 | T4: 1.9701073 | U4: -0.0003048676 | V4: -0.44706048 | W4: 0.038255162 | X4: 0.67802275 | Y4: 0.028772982 | Z4: 0.80661593 | AA4: 0.66724568 | AB4: 0.39315496 | AC4: 0.27678473 | AE4: 0.59454545 | AF4: 0.16530142 | AG4: 3.919871 | AH4: 0.58430584
A5: AAMI | B5: Financials | C5: -0.017036941 | D5: 1.71155e+09 | E5: =SQRT(D5) | F5: =D5/SUM($D$2:$D$2546) | G5: =E5/SUM($E$2:$E$2546) | H5: 0 | I5: 0 | J5: 0 | K5: 0 | L5: 1 | M5: 0 | N5: 0 | O5: 0 | P5: 0 | Q5: 0 | R5: 0 | S5: 21.260665 | T5: 1.0959266 | U5: 0.0024739996 | V5: 0.0053752447 | W5: 0.024519311 | X5: 0.37340689 | Y5: 0.020405506 | Z5: -1.9493274 | AA5: -1.8711976 | AB5: -2.0172983 | AC5: 0.023604335 | AD5: 0.03342 | AE5: -0.61886792 | AF5: -0.0096519325 | AG5: 1.1603809 | AH5: 0.5329466 | AI5: 30.836957
A6: AAOI | B6: Information Technology | C6: -0.091364897 | D6: 1.5718031e+09 | E6: =SQRT(D6) | F6: =D6/SUM($D$2:$D$2546) | G6: =E6/SUM($E$2:$E$2546) | H6: 0 | I6: 0 | J6: 0 | K6: 0 | L6: 0 | M6: 0 | N6: 0 | O6: 1 | P6: 0 | Q6: 0 | R6: 0 | S6: 21.175489 | T6: 3.6933827 | U6: 0.0029723395 | V6: 0.27037802 | W6: 0.073293101 | X6: 1.3378781 | Y6: 0.050455332 | Z6: 0.43124945 | AA6: 0.41276059 | AB6: 0.19024399 | AC6: -0.023153028 | AD6: -0.0068660002 | AE6: -0.25714286 | AF6: 0.048026945 | AG6: 1.0852117 | AH6: 0.26506996 | AI6: 1.3151576
A7: AAON | B7: Industrials | C7: -0.060461855 | D7: 7.1909707e+09 | E7: =SQRT(D7) | F7: =D7/SUM($D$2:$D$2546) | G7: =E7/SUM($E$2:$E$2546) | H7: 0 | I7: 0 | J7: 0 | K7: 0 | L7: 0 | M7: 0 | N7: 1 | O7: 0 | P7: 0 | Q7: 0 | R7: 0 | S7: 22.696092 | T7: 1.525467 | U7: -0.0013719621 | V7: 0.11580439 | W7: 0.041594233 | X7: 0.6347036 | Y7: 0.038954852 | Z7: -0.84394001 | AA7: -1.1709759 | AB7: -1.614186 | AC7: 0.0086146923 | AD7: 0.012698703 | AE7: 0.31276588 | AF7: 0.2402752 | AG7: 1.0441216 | AH7: 0.23994203 | AI7: 1.3810009
A8: AAP | B8: Consumer Discretionary | C8: -0.083648981 | D8: 3.6697667e+09 | E8: =SQRT(D8) | F8: =D8/SUM($D$2:$D$2546) | G8: =E8/SUM($E$2:$E$2546) | H8: 0 | I8: 1 | J8: 0 | K8: 0 | L8: 0 | M8: 0 | N8: 0 | O8: 0 | P8: 0 | Q8: 0 | R8: 0 | S8: 22.023394 | T8: 0.95956247 | U8: 0.0017841411 | V8: 0.60031065 | W8: 0.05849045 | X8: 0.51300846 | Y8: 0.059631371 | Z8: -0.19108738 | AA8: 0.13398683 | AB8: -0.058481313 | AC8: 0.016349813 | AD8: 0.078479104 | AE8: -0.89023681 | AF8: -0.058785395 | AG8: 1.4065654 | AH8: 0.34595313 | AI8: 1.6772583
A9: AAPL | B9: Information Technology | C9: -0.0023599661 | D9: 3.422233e+12 | E9: =SQRT(D9) | F9: =D9/SUM($D$2:$D$2546) | G9: =E9/SUM($E$2:$E$2546) | H9: 0 | I9: 0 | J9: 0 | K9: 0 | L9: 0 | M9: 0 | N9: 0 | O9: 1 | P9: 0 | Q9: 0 | R9: 0 | S9: 28.861314 | T9: 1.3324555 | U9: -2.604094e-05 | V9: 0.019235979 | W9: 0.021098596 | X9: 0.20727109 | Y9: 0.013774332 | Z9: -2.412995 | AA9: -2.5182625 | AB9: -2.5665979 | AC9: 0.027390304 | AD9: 0.030698085 | AE9: -0.003257329 | AF9: -0.004226679 | AG9: 1.0240866 | AH9: 0.30678592 | AI9: 2.2521647
A10: AAT | B10: Real Estate | C10: -0.0086802152 | D10: 1.1671658e+09 | E10: =SQRT(D10) | F10: =D10/SUM($D$2:$D$2546) | G10: =E10/SUM($E$2:$E$2546) | H10: 0 | I10: 0 | J10: 0 | K10: 0 | L10: 0 | M10: 0 | N10: 0 | O10: 0 | P10: 0 | Q10: 1 | R10: 0 | S10: 20.877844 | T10: 0.76820743 | U10: -0.00020937987 | V10: 1.0145302 | W10: 0.018338504 | X10: 0.47198214 | Y10: 0.015587577 | Z10: -1.9959232 | AA10: -1.848096 | AB10: -2.1081381 | AC10: 0.024404416 | AD10: 0.13675178 | AE10: 0.20606061 | AF10: 0.062349322 | AG10: 2.4450672 | AH10: 0.57716069 | AI10: 2.4243707
A11: ABAT | B11: Materials | C11: 0.096413729 | D11: 3.2532184e+08 | E11: =SQRT(D11) | F11: =D11/SUM($D$2:$D$2546) | G11: =E11/SUM($E$2:$E$2546) | H11: 0 | I11: 0 | J11: 0 | K11: 0 | L11: 0 | M11: 0 | N11: 0 | O11: 0 | P11: 1 | Q11: 0 | R11: 0 | S11: 19.600326 | T11: 1.143325 | U11: 0.002031939 | V11: 0.21701286 | W11: 0.073801821 | X11: 0.51849305 | Y11: 0.06318247 | Z11: 0.29638083 | AA11: -0.40989788 | AB11: -0.78742765 | AC11: -0.12506511 | AD11: -0.10877784 | AE11: 0.020780649 | AF11: 1.1406956 | AG11: 1.0005845 | AH11: 0.095145527 | AI11: 1.0026936
A12: ABBV | B12: Health Care | C12: 0.015807238 | D12: 3.5070471e+11 | E12: =SQRT(D12) | F12: =D12/SUM($D$2:$D$2546) | G12: =E12/SUM($E$2:$E$2546) | H12: 0 | I12: 0 | J12: 0 | K12: 0 | L12: 0 | M12: 1 | N12: 0 | O12: 0 | P12: 0 | Q12: 0 | R12: 0 | S12: 26.58321 | T12: 0.50651408 | U12: 0.00025254639 | V12: -0.00052180651 | W12: 0.016261117 | X12: 0.18600831 | Y12: 0.014462801 | Z12: -2.8215021 | AA12: -2.6553995 | AB12: -2.5976462 | AC12: 0.010698459 | AD12: 0.034079953 | AE12: -0.53929511 | AF12: -0.0059136606 | AG12: 1.1795214 | AH12: 0.51377732
A13: ABCB | B13: Financials | C13: -0.0048981798 | D13: 4.846413e+09 | E13: =SQRT(D13) | F13: =D13/SUM($D$2:$D$2546) | G13: =E13/SUM($E$2:$E$2546) | H13: 0 | I13: 0 | J13: 0 | K13: 0 | L13: 1 | M13: 0 | N13: 0 | O13: 0 | P13: 0 | Q13: 0 | R13: 0 | S13: 22.301505 | T13: 1.070134 | U13: 0.00085016106 | V13: 0.80836651 | W13: 0.019690052 | X13: 0.24707237 | Y13: 0.013143255 | Z13: -1.8749674 | AA13: -2.1244307 | AB13: -2.0759857 | AC13: 0.090651786 | AD13: 0.094015924 | AE13: -0.036214834 | AF13: 0.031800848 | AG13: 1.1052337 | AH13: 0.019115558 | AI13: 1.1301807
A14: ABG | B14: Consumer Discretionary | C14: -0.0040380612 | D14: 4.7275548e+09 | E14: =SQRT(D14) | F14: =D14/SUM($D$2:$D$2546) | G14: =E14/SUM($E$2:$E$2546) | H14: 0 | I14: 1 | J14: 0 | K14: 0 | L14: 0 | M14: 0 | N14: 0 | O14: 0 | P14: 0 | Q14: 0 | R14: 0 | S14: 22.276674 | T14: 1.0499369 | U14: 0.0002909028 | V14: 0.79893311 | W14: 0.024948131 | X14: 0.34969276 | Y14: 0.02145676 | Z14: -1.3882797 | AA14: -1.6756343 | AB14: -1.5269973 | AC14: 0.12928459 | AD14: 0.14536056 | AE14: -0.36543106 | AF14: 0.14963615 | AG14: 1.6269837 | AH14: 0.44938608 | AI14: 1.7847763
A15: ABM | B15: Industrials | C15: -0.023285361 | D15: 2.9443023e+09 | E15: =SQRT(D15) | F15: =D15/SUM($D$2:$D$2546) | G15: =E15/SUM($E$2:$E$2546) | H15: 0 | I15: 0 | J15: 0 | K15: 0 | L15: 0 | M15: 0 | N15: 1 | O15: 0 | P15: 0 | Q15: 0 | R15: 0 | S15: 21.803138 | T15: 0.80615277 | U15: -9.9061361e-06 | V15: 0.62181115 | W15: 0.018989943 | X15: 0.20624634 | Y15: 0.016257279 | Z15: -1.9952296 | AA15: -1.6945957 | AB15: -1.7926951 | AC15: 0.056787647 | AD15: 0.0749923 | AE15: -0.37763466 | AF15: 0.034176339 | AG15: 1.5095944 | AH15: 0.31162129 | AI15: 1.8195324
A16: ABNB | B16: Consumer Discretionary | C16: 0.00072231102 | D16: 5.2970384e+10 | E16: =SQRT(D16) | F16: =D16/SUM($D$2:$D$2546) | G16: =E16/SUM($E$2:$E$2546) | H16: 0 | I16: 1 | J16: 0 | K16: 0 | L16: 0 | M16: 0 | N16: 0 | O16: 0 | P16: 0 | Q16: 0 | R16: 0 | S16: 24.692999 | T16: 1.388578 | U16: 6.0444995e-05 | V16: 0.14691228 | W16: 0.0250426 | X16: 0.26466814 | Y16: 0.016552777 | Z16: -1.3499742 | AA16: -1.4058817 | AB16: -1.4064728 | AC16: 0.04847992 | AD16: 0.050367768 | AE16: 0.49390164 | AF16: 0.19031912 | AG16: 1.0376626 | AH16: 0.084543568 | AI16: 1.2563608
A17: ABR | B17: Financials | C17: -0.012505293 | D17: 2.2266924e+09 | E17: =SQRT(D17) | F17: =D17/SUM($D$2:$D$2546) | G17: =E17/SUM($E$2:$E$2546) | H17: 0 | I17: 0 | J17: 0 | K17: 0 | L17: 1 | M17: 0 | N17: 0 | O17: 0 | P17: 0 | Q17: 0 | R17: 0 | S17: 21.523783 | T17: 0.9055481 | U17: -0.00024606329 | V17: 1.3359474 | W17: 0.022969144 | X17: 0.29708366 | Y17: 0.020724882 | Z17: -1.2031588 | AA17: -1.0321294 | AB17: -1.1059137 | AC17: 0.061605275 | AD17: 0.072110543 | AE17: -0.18826896 | AF17: 0.032380994 | AG17: 3.7109545 | AH17: 0.4379865 | AI17: 3.0292375
A18: ABSI | B18: Health Care | C18: -0.039220676 | D18: 4.6915916e+08 | E18: =SQRT(D18) | F18: =D18/SUM($D$2:$D$2546) | G18: =E18/SUM($E$2:$E$2546) | H18: 0 | I18: 0 | J18: 0 | K18: 0 | L18: 0 | M18: 1 | N18: 0 | O18: 0 | P18: 0 | Q18: 0 | R18: 0 | S18: 19.966453 | T18: 1.4410728 | U18: -0.0020030461 | V18: 0.36953984 | W18: 0.052118948 | X18: 0.78136087 | Y18: 0.042944528 | Z18: -0.010012825 | AA18: -0.41564184 | AB18: -0.73907991 | AC18: -0.26062797 | AD18: -0.2350503 | AE18: 0.25102421 | AF18: -0.014878976 | AG18: 1.0003432 | AH18: 0.035313399 | AI18: 1.0009286
A19: ABT | B19: Health Care | C19: -0.00092766302 | D19: 2.2288485e+11 | E19: =SQRT(D19) | F19: =D19/SUM($D$2:$D$2546) | G19: =E19/SUM($E$2:$E$2546) | H19: 0 | I19: 0 | J19: 0 | K19: 0 | L19: 0 | M19: 1 | N19: 0 | O19: 0 | P19: 0 | Q19: 0 | R19: 0 | S19: 26.129921 | T19: 0.24699046 | U19: 0.00061871705 | V19: 0.22686602 | W19: 0.015693613 | X19: 0.22647989 | Y19: 0.016089722 | Z19: -2.3415709 | AA19: -2.5244816 | AB19: -2.6082629 | AC19: 0.0319268 | AD19: 0.039464324 | AE19: 0.37424319 | AF19: -0.016396997 | AG19: 1.058012 | AH19: 0.15996619 | AI19: 1.2557105
A20: ABUS | B20: Health Care | C20: 0 | D20: 6.4813192e+08 | E20: =SQRT(D20) | F20: =D20/SUM($D$2:$D$2546) | G20: =E20/SUM($E$2:$E$2546) | H20: 0 | I20: 0 | J20: 0 | K20: 0 | L20: 0 | M20: 1 | N20: 0 | O20: 0 | P20: 0 | Q20: 0 | R20: 0 | S20: 20.289605 | T20: 0.88176684 | U20: -0.00034101865 | V20: 0.12802332 | W20: 0.024467741 | X20: 0.43140155 | Y20: 0.019374385 | Z20: -2.6144475 | AA20: -2.4914714 | AB20: -2.2836609 | AC20: 0.015570904 | AD20: 0.015638792 | AE20: 0.25971564 | AF20: -0.19014788 | AG20: 1.0008872 | AH20: 0.010545479 | AI20: 1.0069297
A21: ACA | B21: Industrials | C21: -0.031520264 | D21: 4.9109531e+09 | E21: =SQRT(D21) | F21: =D21/SUM($D$2:$D$2546) | G21: =E21/SUM($E$2:$E$2546) | H21: 0 | I21: 0 | J21: 0 | K21: 0 | L21: 0 | M21: 0 | N21: 1 | O21: 0 | P21: 0 | Q21: 0 | R21: 0 | S21: 22.314734 | T21: 1.1325367 | U21: -2.3401514e-05 | V21: 0.51075626 | W21: 0.025624024 | X21: 0.30158613 | Y21: 0.021664625 | Z21: -1.9285678 | AA21: -2.1415004 | AB21: -2.134595 | AC21: 0.048625999 | AD21: 0.094319778 | AE21: -0.01263877 | AF21: 0.072757453 | AG21: 1.3407282 | AH21: 0.33592066 | AI21: 1.6671052
A22: ACAD | B22: Health Care | C22: -0.024165432 | D22: 4.2515389e+09 | E22: =SQRT(D22) | F22: =D22/SUM($D$2:$D$2546) | G22: =E22/SUM($E$2:$E$2546) | H22: 0 | I22: 0 | J22: 0 | K22: 0 | L22: 0 | M22: 1 | N22: 0 | O22: 0 | P22: 0 | Q22: 0 | R22: 0 | S22: 22.170547 | T22: 0.84149123 | U22: 0.00098104296 | V22: 0.19343161 | W22: 0.03169725 | X22: 0.31015766 | Y22: 0.031970625 | Z22: -1.5398424 | AA22: -1.3186549 | AB22: -1.431447 | AC22: 0.025088327 | AD22: 0.02784968 | AE22: 0.79709443 | AF22: 0.24279856 | AG22: 1.0104906 | AH22: 0.045933475 | AI22: 1.0542339
A23: ACCO | B23: Industrials | C23: 0 | D23: 3.3776065e+08 | E23: =SQRT(D23) | F23: =D23/SUM($D$2:$D$2546) | G23: =E23/SUM($E$2:$E$2546) | H23: 0 | I23: 0 | J23: 0 | K23: 0 | L23: 0 | M23: 0 | N23: 1 | O23: 0 | P23: 0 | Q23: 0 | R23: 0 | S23: 19.637848 | T23: 1.2407156 | U23: -0.0014636988 | V23: 1.8868391 | W23: 0.027781954 | X23: 0.6405799 | Y23: 0.022257844 | Z23: -1.9892858 | AA23: -1.7663499 | AB23: -1.7879998 | AC23: 0.345807 | AD23: 0.48318239 | AE23: -1.0368 | AF23: -0.063817771 | AG23: 3.7951746 | AH23: 0.4516319 | AI23: 2.4814059
A24: ACDC | B24: Energy | C24: -0.033616645 | D24: 6.5656241e+08 | E24: =SQRT(D24) | F24: =D24/SUM($D$2:$D$2546) | G24: =E24/SUM($E$2:$E$2546) | H24: 0 | I24: 0 | J24: 0 | K24: 1 | L24: 0 | M24: 0 | N24: 0 | O24: 0 | P24: 0 | Q24: 0 | R24: 0 | S24: 20.302528 | T24: 2.1384412 | U24: 0.00055901742 | V24: 1.3334604 | W24: 0.077581298 | X24: 2.1504937 | Y24: 0.093383961 | Z24: -2.0597766 | AA24: -2.1685713 | AB24: -2.4565021 | AC24: -0.64517857 | AD24: -0.0073108053 | AE24: -0.69428113 | AF24: 0.22317933 | AG24: 2.4441887 | AH24: 0.43363832 | AI24: 2.0830383
... A26: ACGL | B26: Financials | C26: 0.016647782 | D26: 3.2618202e+10 | E26: =SQRT(D26) | F26: =D26/SUM($D$2:$D$2546) | G26: =E26/SUM($E$2:$E$2546) | H26: 0 | I26: 0 | J26: 0 | K26: 0 | L26: 1 | M26: 0 | N26: 0 | O26: 0 | P26: 0 | Q26: 0 | R26: 0 | S26: 24.208136 | T26: 0.51248319 | U26: -0.00022656355 | V26: 0.70638474 | W26: 0.016460265 | X26: 0.21629086 | Y26: 0.015254259 | Z26: -1.872507 | AA26: -2.0925195 | AB26: -2.23296 | AC26: 0.15169444 | AD26: 0.15758073 | AE26: 0.32379786 | AF26: 0.22726247 | AG26: 1.1090802 | AH26: 0.034624562 | AI26: 1.1544204
A27: ACH | B27: Health Care | C27: 0.013047747 | D27: 4.1225734e+08 | E27: =SQRT(D27) | F27: =D27/SUM($D$2:$D$2546) | G27: =E27/SUM($E$2:$E$2546) | H27: 0 | I27: 0 | J27: 0 | K27: 0 | L27: 0 | M27: 1 | N27: 0 | O27: 0 | P27: 0 | Q27: 0 | R27: 0 | S27: 19.837158 | T27: 1.2198148 | U27: -0.0027276732 | V27: -0.68163735 | W27: 0.068338694 | X27: 4.3065347 | Y27: 0.074277767 | Z27: -0.86494177 | AA27: -0.9694652 | AB27: -1.1044452 | AC27: -8.4321895 | AD27: -7.8558601 | AE27: -1.1220418 | AF27: 0.030657481 | AG27: 4.8683241 | AH27: 0.49553609
A28: ACHC | B28: Health Care | C28: -0.0053102036 | D28: 1.8785273e+09 | E28: =SQRT(D28) | F28: =D28/SUM($D$2:$D$2546) | G28: =E28/SUM($E$2:$E$2546) | H28: 0 | I28: 0 | J28: 0 | K28: 0 | L28: 0 | M28: 1 | N28: 0 | O28: 0 | P28: 0 | Q28: 0 | R28: 0 | S28: 21.353754 | T28: 0.88313697 | U28: -0.0037854654 | V28: 1.6385101 | W28: 0.039226737 | X28: 4.5396451 | Y28: 0.03770174 | Z28: -0.64456631 | AA28: -0.75044663 | AB28: -0.79731923 | AC28: 0.064150251 | AD28: 0.16847665 | AE28: -0.066585662 | AF28: 0.10309507 | AG28: 2.1961641 | AH28: 0.37818187 | AI28: 1.7300316
A29: ACHR | B29: Industrials | C29: -0.020803132 | D29: 7.4879133e+09 | E29: =SQRT(D29) | F29: =D29/SUM($D$2:$D$2546) | G29: =E29/SUM($E$2:$E$2546) | H29: 0 | I29: 0 | J29: 0 | K29: 0 | L29: 0 | M29: 0 | N29: 1 | O29: 0 | P29: 0 | Q29: 0 | R29: 0 | S29: 22.736556 | T29: 2.3329381 | U29: 0.00338779 | V29: 0.22448177 | W29: 0.058518447 | X29: 0.95426179 | Y29: 0.050105853 | Z29: 0.11490508 | AA29: 0.14150845 | AB29: -0.15854703 | AC29: -0.11004401 | AD29: -0.10747988 | AE29: 0.25310436 | AG29: 1.0085605 | AH29: 0.042098746 | AI29: 1.0381343
A30: ACI | B30: Consumer Staples | C30: -0.0020965292 | D30: 9.6540628e+09 | E30: =SQRT(D30) | F30: =D30/SUM($D$2:$D$2546) | G30: =E30/SUM($E$2:$E$2546) | H30: 0 | I30: 0 | J30: 1 | K30: 0 | L30: 0 | M30: 0 | N30: 0 | O30: 0 | P30: 0 | Q30: 0 | R30: 0 | S30: 22.990645 | T30: 0.010148312 | U30: 0.00017830204 | V30: 0.33398374 | W30: 0.017214592 | X30: 0.21005915 | Y30: 0.015423003 | Z30: -1.3143564 | AA30: -1.4626378 | AB30: -1.5216773 | AC30: 0.0979484 | AD30: 0.42394587 | AE30: -0.1470852 | AF30: 0.035061761 | AG30: 1.7256634 | AH30: 0.54078233 | AI30: 3.1727507
A31: ACIC | B31: Financials | C31: 0.01731244 | D31: 4.9906016e+08 | E31: =SQRT(D31) | F31: =D31/SUM($D$2:$D$2546) | G31: =E31/SUM($E$2:$E$2546) | H31: 0 | I31: 0 | J31: 0 | K31: 0 | L31: 1 | M31: 0 | N31: 0 | O31: 0 | P31: 0 | Q31: 0 | R31: 0 | S31: 20.028237 | T31: 0.42314812 | U31: -0.00035115666 | V31: 0.58570093 | W31: 0.023167268 | X31: 0.41280502 | Y31: 0.021851621 | Z31: -2.5057121 | AA31: -2.2441657 | AB31: -2.3894349 | AC31: 0.21193437 | AD31: 0.22548785 | AE31: 0.51221374 | AF31: 0.097524525 | AG31: 1.2989359 | AH31: 0.11317764 | AI31: 1.51039
A32: ACIW | B32: Information Technology | C32: -0.014483753 | D32: 4.8750319e+09 | E32: =SQRT(D32) | F32: =D32/SUM($D$2:$D$2546) | G32: =E32/SUM($E$2:$E$2546) | H32: 0 | I32: 0 | J32: 0 | K32: 0 | L32: 0 | M32: 0 | N32: 0 | O32: 1 | P32: 0 | Q32: 0 | R32: 0 | S32: 22.307392 | T32: 1.2072016 | U32: -0.00017596661 | V32: 0.28584387 | W32: 0.022831293 | X32: 0.328698 | Y32: 0.018738124 | Z32: -1.6768312 | AA32: -1.8512449 | AB32: -1.9059763 | AC32: 0.010011832 | AD32: 0.029786882 | AE32: 0.17736549 | AF32: 0.04807015 | AG32: 1.1758167 | AH32: 0.29638181 | AI32: 1.6150795
A33: ACLS | B33: Information Technology | C33: -0.014342675 | D33: 2.6085111e+09 | E33: =SQRT(D33) | F33: =D33/SUM($D$2:$D$2546) | G33: =E33/SUM($E$2:$E$2546) | H33: 0 | I33: 0 | J33: 0 | K33: 0 | L33: 0 | M33: 0 | N33: 0 | O33: 1 | P33: 0 | Q33: 0 | R33: 0 | S33: 21.682045 | T33: 1.5451781 | U33: -0.00063607594 | V33: 0.3919412 | W33: 0.035594578 | X33: 0.79346116 | Y33: 0.030666693 | Z33: -0.91310196 | AA33: -0.96433445 | AB33: -0.84010952 | AC33: 0.04811327 | AD33: 0.055036759 | AE33: 0.2105548 | AF33: 0.13690195 | AG33: 1.0159351 | AH33: 0.032492977 | AI33: 1.040657
A34: ACLX | B34: Health Care | C34: 0.011617484 | D34: 4.1071585e+09 | E34: =SQRT(D34) | F34: =D34/SUM($D$2:$D$2546) | G34: =E34/SUM($E$2:$E$2546) | H34: 0 | I34: 0 | J34: 0 | K34: 0 | L34: 0 | M34: 1 | N34: 0 | O34: 0 | P34: 0 | Q34: 0 | R34: 0 | S34: 22.135997 | T34: 1.0438191 | U34: 0.00012410061 | V34: 0.095497411 | W34: 0.030512006 | X34: 0.58686633 | Y34: 0.029063952 | Z34: -1.6542212 | AA34: -1.5071973 | AB34: -1.5054768 | AC34: -0.05139417 | AD34: -0.049818385 | AE34: 0.13326851 | AF34: 0.79563263 | AG34: 1.0109801 | AH34: 0.084823433 | AI34: 1.114978
A35: ACM | B35: Industrials | C35: -0.015693696 | D35: 1.5694342e+10 | E35: =SQRT(D35) | F35: =D35/SUM($D$2:$D$2546) | G35: =E35/SUM($E$2:$E$2546) | H35: 0 | I35: 0 | J35: 0 | K35: 0 | L35: 0 | M35: 0 | N35: 1 | O35: 0 | P35: 0 | Q35: 0 | R35: 0 | S35: 23.476566 | T35: 0.75111713 | U35: 0.00081852989 | V35: 0.158805 | W35: 0.014749155 | X35: 0.16963771 | Y35: 0.011496344 | Z35: -1.8697416 | AA35: -1.9138406 | AB35: -1.9072834 | AC35: 0.033379163 | AD35: 0.044733063 | AE35: 0.20430108 | AF35: 0.10166758 | AG35: 1.1564803 | AH35: 0.24897861 | AI35: 1.9853611
A36: ACMR | B36: Information Technology | C36: 0.00078525557 | D36: 1.5238991e+09 | E36: =SQRT(D36) | F36: =D36/SUM($D$2:$D$2546) | G36: =E36/SUM($E$2:$E$2546) | H36: 0 | I36: 0 | J36: 0 | K36: 0 | L36: 0 | M36: 0 | N36: 0 | O36: 1 | P36: 0 | Q36: 0 | R36: 0 | S36: 21.144538 | T36: 1.6122109 | U36: 0.0020393484 | V36: 0.64731977 | W36: 0.043218453 | X36: 0.55554286 | Y36: 0.034485771 | Z36: -0.82474833 | AA36: -1.0462131 | AB36: -0.7149841 | AC36: 0.078115409 | AD36: 0.086879769 | AE36: 0.3444619 | AF36: 0.34921968 | AG36: 1.1069566 | AH36: 0.1408888 | AI36: 1.1652299
A37: ACN | B37: Information Technology | C37: 0.0019518996 | D37: 1.5120011e+11 | E37: =SQRT(D37) | F37: =D37/SUM($D$2:$D$2546) | G37: =E37/SUM($E$2:$E$2546) | H37: 0 | I37: 0 | J37: 0 | K37: 0 | L37: 0 | M37: 0 | N37: 0 | O37: 1 | P37: 0 | Q37: 0 | R37: 0 | S37: 25.74187 | T37: 0.88974564 | U37: -0.0011219195 | V37: 0.20208137 | W37: 0.01884532 | X37: 0.47785305 | Y37: 0.015539635 | Z37: -1.8491125 | AA37: -2.0351645 | AB37: -2.2565703 | AC37: 0.058134907 | AD37: 0.065859901 | AE37: 0.031493701 | AF37: 0.025987267 | AG37: 1.0333067 | AH37: 0.12886674 | AI37: 1.1648182
A38: ACNB | B38: Financials | C38: -0.0033190435 | D38: 4.6242714e+08 | E38: =SQRT(D38) | F38: =D38/SUM($D$2:$D$2546) | G38: =E38/SUM($E$2:$E$2546) | H38: 0 | I38: 0 | J38: 0 | K38: 0 | L38: 1 | M38: 0 | N38: 0 | O38: 0 | P38: 0 | Q38: 0 | R38: 0 | S38: 19.952 | T38: 0.61192443 | U38: 0.00043028369 | V38: 0.85451516 | W38: 0.017159768 | X38: 0.2167181 | Y38: 0.012358702 | Z38: -3.1409807 | AA38: -2.9335829 | AB38: -2.954333 | AC38: 0.10075533 | AD38: 0.110625 | AE38: 0.033760972 | AF38: 0.04311412 | AG38: 1.5522038 | AH38: 0.08752801 | AI38: 1.6462188
A39: ACRE | B39: Financials | C39: -0.0022101046 | D39: 2.3406827e+08 | E39: =SQRT(D39) | F39: =D39/SUM($D$2:$D$2546) | G39: =E39/SUM($E$2:$E$2546) | H39: 0 | I39: 0 | J39: 0 | K39: 0 | L39: 1 | M39: 0 | N39: 0 | O39: 0 | P39: 0 | Q39: 0 | R39: 0 | S39: 19.271123 | T39: 1.0076921 | U39: -0.00091165217 | V39: 2.2373772 | W39: 0.028477241 | X39: 0.67236118 | Y39: 0.025172611 | Z39: -1.698154 | AA39: -1.7346063 | AB39: -1.5689317 | AC39: -0.18857746 | AD39: -0.148948 | AE39: -0.89139466 | AF39: -0.49323543 | AG39: 2.0525434 | AH39: 0.61739576 | AI39: 1.4704363
A40: ACT | B40: Financials | C40: 0.0020936837 | D40: 5.4505028e+09 | E40: =SQRT(D40) | F40: =D40/SUM($D$2:$D$2546) | G40: =E40/SUM($E$2:$E$2546) | H40: 0 | I40: 0 | J40: 0 | K40: 0 | L40: 1 | M40: 0 | N40: 0 | O40: 0 | P40: 0 | Q40: 0 | R40: 0 | S40: 22.418974 | T40: 0.47231458 | U40: 0.00034446525 | V40: 0.95828369 | W40: 0.0141208 | X40: 0.13522887 | Y40: 0.012604341 | Z40: -3.1650235 | AA40: -2.8256719 | AB40: -2.9012389 | AC40: 0.12315047 | AE40: 0.0093312597 | AF40: 0.026609106 | AG40: 1.1364559 | AH40: 0.10980379 | AI40: 1.1423961
A41: ACTG | B41: Financials | C41: -0.020558778 | D41: 3.3182371e+08 | E41: =SQRT(D41) | F41: =D41/SUM($D$2:$D$2546) | G41: =E41/SUM($E$2:$E$2546) | H41: 0 | I41: 0 | J41: 0 | K41: 0 | L41: 1 | M41: 0 | N41: 0 | O41: 0 | P41: 0 | Q41: 0 | R41: 0 | S41: 19.620114 | T41: 0.81629175 | U41: -0.0007513466 | V41: 1.6230908 | W41: 0.028022038 | X41: 0.52880782 | Y41: 0.027578179 | Z41: -3.1104941 | AA41: -3.1766654 | AB41: -2.8881989 | AC41: -0.039695778 | AD41: 0.098269049 | AE41: -0.2712782 | AF41: 0.17094587 | AG41: 1.3073409 | AH41: 0.14959138 | AI41: 1.1893553
...

Sheet ZScoring
A1: Ticker | B1: z(dastd) | C1: z(cmra) | D1: z(hsigma) | E1: z(stom) | F1: z(stoq) | G1: z(stoa) | H1: z(etop) | I1: z(cetop) | J1: z(egro) | K1: z(sgro) | L1: z(mlev) | M1: z(dtoa) | N1: z(blev) | O1: residvol_comp | P1: liq_comp | Q1: earnyild_comp | R1: growth_comp | S1: leverage_comp | T1: nlsize_raw | U1: z_pre(size) | V1: z_pre(beta) | W1: z_pre(momentum) | X1: z_pre(residvol) | Y1: z_pre(nlsize) | Z1: z_pre(btop) | AA1: z_pre(liquidity) | AB1: z_pre(earnyild) | AC1: z_pre(growth) | AD1: z_pre(leverage) | AE1: nlsize_orth | AF1: residvol_orth | AG1: liq_orth | AH1: py_size | AI1: py_beta | AJ1: py_momentum | AK1: py_residvol | AL1: py_nlsize | AM1: py_btop | AN1: py_liquidity | AO1: py_earnyild | AP1: py_growth | AQ1: py_leverage
